Workbook

Sheet CO-PO Mapping
A1: Sanjivani Rural Educational Society’s
A2: SANJIVANI COLLEGE OF ENGINEERING
A3: (An Autonomous Institute)
A4: Kopargaon – 423 603, Maharashtra
A6: Academic Year | B6: Department of ________________Engineering | D6: ACAD-F-15C
A7: 2023-2024
A8: Sem | B8: CO-PO Mapping Articulation Matrix and Justification | D8: Rev Dated:
A9: ODD/ EVEN | D9: 22.1.2024
A10: NAME OF THE FACULTY
A11: CLASS / DIV
A12: YEAR / SEM
A13: COURSE CODE AND COURSE NAME
A15: CO | B15: Course Outcomes
A16: CO1
A17: CO2
A18: CO3
A19: CO4
A20: CO5
A21: CO6
A24: % Mapping | B24: Rubrics- Mapping Level
A25: Between 0 to 15 % | B25: 0
A26: Between 15% to 35% | B26: 1
A27: Between 36 to 65% | B27: 2
A28: More than 65% | B28: 3
B30: Define the own Performance Indicator based on AICTE Examination Reform Policy
A32: PO 1: Engineering knowledge: Apply the knowledge of mathematics, science, engineering fundamentals, and an engineering specialization for the solution of complex engineering problems.
A33: Competency | B33: Indicators | C33: CO1 | D33: CO2 | E33: CO3 | F33: CO4 | G33: CO5 | H33: CO6
A34: 1.1 Demonstrate competence in mathematical modelling | B34: 1.1.1 Apply mathematical techniques such as calculus, linear algebra, and statistics to solve problems
B35: 1.1.2 Apply advanced mathematical techniques to model and solve computer engineering problems
A36: 1.2 Demonstrate competence in basic sciences | B36: 1.2.1 Apply laws of natural science to an engineering problem | C36: Y | D36: Y | E36: Y | F36: Y | G36: Y | H36: Y
A37: 1.3 Demonstrate competence in engineering fundamentals | B37: 1.3.1 Apply fundamental engineering concepts to solve engineering problems | C37: Y | D37: Y | E37: Y | F37: Y | G37: Y | H37: Y
A38: 1.4 Demonstrate competence in specialized engineering knowledge to the program | B38: 1.4.1 Apply engineering concepts to solve Computer Science and Enginering engineering problems. | C38: Y | D38: Y | E38: Y | F38: Y | G38: Y | H38: Y
A39: Total Indicators | B39: 5 | C39: =COUNTIF(C33:C38,"=y") -> 3 | D39: =COUNTIF(D33:D38,"=y") -> 3 | E39: =COUNTIF(E33:E38,"=y") -> 3 | F39: =COUNTIF(F33:F38,"=y") -> 3 | G39: =COUNTIF(G33:G38,"=y") -> 3 | H39: =COUNTIF(H33:H38,"=y") -> 3
B40: % of Mapping | C40: =C39*100/B39 -> 60 | D40: =D39*100/5 -> 60 | E40: =E39*100/5 -> 60 | F40: =F39*100/5 -> 60 | G40: =G39*100/5 -> 60 | H40: =H39*100/5 -> 60
A41: PO1 | B41: Indicators | C41: =IF(C40>=65,"3",IF(C40>=36,"2",IF(C40>=15,"1",IF(C40<15,"0")))) -> 2 | D41: =IF(D40>=65,"3",IF(D40>=36,"2",IF(D40>=15,"1",IF(D40<15,"0")))) -> 2 | E41: =IF(E40>=65,"3",IF(E40>=36,"2",IF(E40>=15,"1",IF(E40<15,"0")))) -> 2 | F41: =IF(F40>=65,"3",IF(F40>=36,"2",IF(F40>=15,"1",IF(F40<15,"0")))) -> 2 | G41: =IF(G40>=65,"3",IF(G40>=36,"2",IF(G40>=15,"1",IF(G40<15,"0")))) -> 2 | H41: =IF(H40>=65,"3",IF(H40>=36,"2",IF(H40>=15,"1",IF(H40<15,"0")))) -> 2
A42: PO 2: Problem analysis: Identify, formulate, research literature, and analyse complex engineering problems reaching substantiated conclusions using first principles of mathematics, natural sciences, and engineering sciences.
A43: Competency | B43: Indicators | C43: CO1 | D43: CO2 | E43: CO3 | F43: CO4 | G43: CO5 | H43: CO6
A44: 2.1 Demonstrate an ability to identify and formulate complex engineering problem | B44: 2.1.1 Articulate problem statements and identify objectives | C44: Y | D44: Y | E44: Y | F44: Y | G44: Y | H44: Y
B45: 2.1.2 Identify engineering systems, variables, and parameters to solve the problems | C45: Y | D45: Y | E45: Y | F45: Y | G45: Y | H45: Y
B46: 2.1.3 Identify the mathematical, engineering and other relevant knowledge that applies to a given problem | C46: Y | D46: Y | E46: Y | F46: Y | G46: Y | H46: Y
...

Sheet CO-PO Atriculation Matrix(no)
A1: Sanjivani Rural Educational Society’s
A2: SANJIVANI COLLEGE OF ENGINEERING
A3: (An Autonomous Institution)
A4: Kopargaon – 423 603, Maharashtra
A5: Department of _______________________
N6: ACAD-F-15C
A7: CO-PO Mapping Articulation Matrix and Justification
A10: CO1 | B10: ='CO-PO Mapping'!B16:H16 -> 0
A11: CO2 | B11: ='CO-PO Mapping'!B17:H17 -> 0
A12: CO3 | B12: ='CO-PO Mapping'!B18:H18 -> 0
A13: CO4 | B13: ='CO-PO Mapping'!B19:H19 -> 0
A14: CO5 | B14: ='CO-PO Mapping'!B20:H20 -> 0
A15: CO6 | B15: ='CO-PO Mapping'!B21:H21 -> 0
A20: Mapping of Course Outcomes to Program Outcomes (POs) & Program Specific Outcomes (PSOs):
B21: PO1 | C21: PO2 | D21: PO3 | E21: PO4 | F21: PO5 | G21: PO6 | H21: PO7 | I21: PO8 | J21: PO9 | K21: PO10 | L21: PO11 | M21: PO12 | N21: PSO1 | O21: PSO2
A22: CO1 | B22: ='CO-PO Mapping'!C41 -> 2 | C22: ='CO-PO Mapping'!C59 -> 3 | D22: ='CO-PO Mapping'!C77 -> 1 | E22: ='CO-PO Mapping'!C92 -> 0 | F22: ='CO-PO Mapping'!C103 -> 1 | G22: ='CO-PO Mapping'!C110 -> 0 | H22: ='CO-PO Mapping'!C119 -> 0 | I22: ='CO-PO Mapping'!C127 -> 0 | J22: ='CO-PO Mapping'!C139 -> 0 | K22: ='CO-PO Mapping'!C151 -> 0 | L22: ='CO-PO Mapping'!C161 -> 0 | M22: ='CO-PO Mapping'!C172 -> 1 | N22: 2 | O22: 1
A23: CO2 | B23: ='CO-PO Mapping'!D41 -> 2 | C23: ='CO-PO Mapping'!D59 -> 3 | D23: ='CO-PO Mapping'!D77 -> 2 | E23: ='CO-PO Mapping'!D92 -> 1 | F23: ='CO-PO Mapping'!D103 -> 1 | G23: ='CO-PO Mapping'!D110 -> 0 | H23: ='CO-PO Mapping'!D119 -> 0 | I23: ='CO-PO Mapping'!D127 -> 0 | J23: ='CO-PO Mapping'!D139 -> 0 | K23: ='CO-PO Mapping'!D151 -> 0 | L23: ='CO-PO Mapping'!D161 -> 0 | M23: ='CO-PO Mapping'!D172 -> 1 | N23: 2 | O23: 1
A24: CO3 | B24: ='CO-PO Mapping'!E41 -> 2 | C24: ='CO-PO Mapping'!E59 -> 3 | D24: ='CO-PO Mapping'!E77 -> 1 | E24: ='CO-PO Mapping'!E92 -> 1 | F24: ='CO-PO Mapping'!E103 -> 1 | G24: ='CO-PO Mapping'!E110 -> 0 | H24: ='CO-PO Mapping'!E119 -> 0 | I24: ='CO-PO Mapping'!E127 -> 0 | J24: ='CO-PO Mapping'!E139 -> 0 | K24: ='CO-PO Mapping'!E151 -> 0 | L24: ='CO-PO Mapping'!E161 -> 0 | M24: ='CO-PO Mapping'!E172 -> 1 | N24: 2 | O24: 1
A25: CO4 | B25: ='CO-PO Mapping'!F41 -> 2 | C25: ='CO-PO Mapping'!F59 -> 3 | D25: ='CO-PO Mapping'!F77 -> 1 | E25: ='CO-PO Mapping'!F92 -> 1 | F25: ='CO-PO Mapping'!F103 -> 1 | G25: ='CO-PO Mapping'!F110 -> 0 | H25: ='CO-PO Mapping'!F119 -> 0 | I25: ='CO-PO Mapping'!F127 -> 0 | J25: ='CO-PO Mapping'!F139 -> 0 | K25: ='CO-PO Mapping'!F151 -> 0 | L25: ='CO-PO Mapping'!F161 -> 0 | M25: ='CO-PO Mapping'!F172 -> 1 | N25: 2 | O25: 1
A26: CO5 | B26: ='CO-PO Mapping'!G41 -> 2 | C26: ='CO-PO Mapping'!G59 -> 3 | D26: ='CO-PO Mapping'!G77 -> 1 | E26: ='CO-PO Mapping'!G92 -> 2 | F26: ='CO-PO Mapping'!G103 -> 1 | G26: ='CO-PO Mapping'!G110 -> 0 | H26: ='CO-PO Mapping'!G119 -> 0 | I26: ='CO-PO Mapping'!G127 -> 0 | J26: ='CO-PO Mapping'!G139 -> 0 | K26: ='CO-PO Mapping'!G151 -> 0 | L26: ='CO-PO Mapping'!G161 -> 0 | M26: ='CO-PO Mapping'!G172 -> 1 | N26: 2 | O26: 1
A27: CO6 | B27: ='CO-PO Mapping'!H41 -> 2 | C27: ='CO-PO Mapping'!H59 -> 3 | D27: ='CO-PO Mapping'!H77 -> 1 | E27: ='CO-PO Mapping'!H92 -> 0 | F27: ='CO-PO Mapping'!H103 -> 1 | G27: ='CO-PO Mapping'!H110 -> 0 | H27: ='CO-PO Mapping'!H119 -> 0 | I27: ='CO-PO Mapping'!H127 -> 0 | J27: ='CO-PO Mapping'!H139 -> 0 | K27: ='CO-PO Mapping'!H151 -> 0 | L27: ='CO-PO Mapping'!H161 -> 0 | M27: ='CO-PO Mapping'!H172 -> 1 | N27: 2 | O27: 1
B32: Course Faculty | I32: Course Coordinator | O32: HoD/EE
B33: (Name) | I33: (Name) | O33: (name)
